{
  try {
    CheckException last=null;
    for (    final Throwable ex : Lists.reverse(exs)) {
      if ((last != null) && (ex instanceof CheckException)) {
        last.other=(CheckException)ex;
      }
 else       if (last == null) {
        last=new CheckException(config,severity,ex);
      }
    }
    last=(last != null ? last : new CheckException(config,Severity.DEBUG,new NullPointerException("Faults.chain called w/ empty list: " + exs)));
    return last;
  }
 catch (  Exception ex) {
    LOG.error("Faults: error in processing previous error: " + ex);
    Logs.extreme().error(ex,ex);
    return new CheckException(config,Severity.ERROR,ex);
  }
}
