{
  for (  Callback cb : this.failureCallbacks) {
    try {
      EventRecord.here(cb.getClass(),EventType.CALLBACK,"fireException(" + t.getClass().getName() + ")").debug();
      cb.fire(t);
    }
 catch (    Throwable t2) {
      LOG.error("Exception occurred while trying to call: " + cb.getClass().toString() + ".failure( "+ t.getMessage()+ " )");
      LOG.error(t2,t2);
    }
  }
}
